Workbook

Sheet Candidates
A1: ID | B1: Candidate | C1: Category | D1: Look line | E1: Strongest signal | F1: Signal source | G1: Signal URL | H1: Signal date | I1: Signal verified? | J1: Other signals | K1: Typical retail (seen) | L1: Typical supplier cost (seen) | M1: IP risk | N1: Battery or skin? | O1: Why it will pin | P1: Decision | Q1: Reject reason
A2: C001 | B2: Satin sleep bonnet (adjustable tie band, pink/blush) | C2: beauty-selfcare | D2: The Pink Bedtime Routine / Sunday Reset Self-Care list | E2: Keyword page 'hair bonnets' shows product card with 351.2K sold | F2: TikTok Shop | G2: https://shop.tiktok.com/us/k/hair-bonnets | H2: 2026-09 (search snippet) | I2: seen in snippet (aggregated keyword page; sold count belongs to a product card on that page, exact SKU not confirmed) | J2: TikTok Shop: Keyword page 'satin bonnet for sleep leopard' shows 4.4K sold (https://shop.tiktok.com/us/k/satin-bonnet-for-sleep-leopard) | TikTok Shop: Keyword page 'satin bonnet before and after' shows product cards from 1.3K to 179K sold (https://shop.tiktok.com/us/k/satin-bonnet-before-and-after) | TikTok Shop: Keyword page 'satin vs silk bonnet' shows a card with 2.2M sold (https://shop.tiktok.com/us/k/satin-vs-silk-bonnet) | AliExpress: Two '2026 New' satin bonnet listings live (1005010652557849, 1005010511012337); order counts not visible in snippet (https://www.aliexpress.com/item/1005010652557849.html) | K2: TikTok Shop under $5 to $30+ per snippet; branded Bounce Curl bonnet $22.00 with 2.2K sold (https://shop.tiktok.com/us/k/bounce-curl-satin-bonnet) | L2: unknown (AliExpress listing prices not shown in snippet) | M2: none (avoid K-pop / character-print variants seen on TikTok Shop) | N2: none | O2: A blush satin bonnet with a bow is the hero of every pink 'night routine' flat lay and reads as self-care, not hair care. | P2: BANK Q14
A3: C002 | B3: Spa headband + wrist towel set (bow / coquette style, pink) | C3: beauty-selfcare | D3: The Pink Skincare Shelf / Everything Shower list | E3: Keyword page 'spa headband and wristband' shows product card with 13.7K sold at $2.11 (was $4.39, -52%) | F3: TikTok Shop | G3: https://shop.tiktok.com/us/k/spa-headband-and-wristband | H3: 2026-09 (search snippet) | I3: seen in snippet | J3: TikTok Shop: Keyword page 'spa headband' shows card with 43 sold at $3.28 (was $7.99) (https://shop.tiktok.com/us/k/spa-headband) | K3: TikTok Shop $2.11 to $7.99 (snippet); blush set listing by Gnarley Charley https://shop.tiktok.com/us/pdp/blush-spa-headband-wristband-set-by-gnarley-charley-hair-accessory/1729441297081799237 | L3: unknown | M3: none (skip 'cute bear' / character variants) | N3: none (worn on hair/wrists, not a cosmetic) | O3: Ultra-low price, bow-topped, and the first thing on screen in every GRWM skincare video. | P3: BANK E17
A4: C003 | B4: Travel makeup 'vanity bag' / large-capacity cosmetic case (pink) | C4: beauty-selfcare | D4: The Pink Weekend Trip / Carry-On Essentials list | E4: 'Vanity Bag' approx. 206K searches/month, up 66% YoY (quoted by CJ Dropshipping blog citing Google Trends) | F4: Google Trends | G4: https://cjdropshipping.com/blogs/selling-strategies/google-trends-products | H4: 2026 (CJ blog) | I4: seen in snippet (secondary source quoting Google Trends; not seen directly on trends.google.com) | J4: TikTok Shop: Keyword page 'pink makeup case' shows card with 51 sold at $13.80 (https://shop.tiktok.com/us/k/pink-makeup-case) | K4: TikTok Shop $13.80 to $16.19 (snippet); Amazon Best Sellers Cosmetic Travel Cases page https://www.amazon.com/Best-Sellers-Cosmetic-Travel-Cases/zgbs/beauty/11062811 (ranks not visible) | L4: unknown (CJ product page price not in snippet) | M4: none (avoid 'Saie', 'Rhode', 'Hailey Bieber' branded search terms seen on TikTok Shop) | N4: none | O4: Open-flat pink vanity case with adjustable dividers is the 'what's in my travel bag' pin format that gets saved for the next trip. | P4: BANK E13
A5: C004 | B5: Pink feather-trim pajama set | C5: beauty-selfcare | D5: The Pink Bedtime Routine / Bridal-Shower Loungewear list | E5: Keyword page 'pink feather pajamas' shows card with 3.4K sold at $15.40 (was $19.49, -21%) | F5: TikTok Shop | G5: https://shop.tiktok.com/us/k/pink-feather-pajamas | H5: 2026-09 (search snippet) | I5: seen in snippet | J5: TikTok Shop: Keyword page 'pajama sets' shows card with 249 sold at $70.20 (limited time deal) (https://shop.tiktok.com/us/k/pajama-sets) | K5: TikTok Shop $15.40 to $26.54 (snippet) | L5: unknown | M5: none | N5: none | O5: Feather cuffs in baby pink are the 'Legally Blonde at home' look; it doubles as a gifting pin. | P5: BANK E21
A6: C005 | B6: Pink robe with fur/feather trim | C6: beauty-selfcare | D6: The Pink Bedtime Routine / Getting-Ready Robe list | E6: Keyword page 'pink robe with fur trim' shows card with 592 sold at $41.36 | F6: TikTok Shop | G6: https://shop.tiktok.com/us/k/pink-robe-with-fur-trim | H6: 2026-09 (search snippet) | I6: seen in snippet | J6: TikTok Shop: Keyword page 'fluffy robe' shows card with 11 sold, $6.61 to $9.45 (-30%) (https://shop.tiktok.com/us/k/fluffy-robe) | K6: TikTok Shop $35 to $88 for premium plush (snippet); 'The Viral Robe' pink https://shop.tiktok.com/us/pdp/soliana-signature-robe-by-viral-robe-pink-womens-loungewear/1729481808994734198 | L6: unknown | M6: none (do not market as 'Viral Robe' brand) | N6: none | O6: The pink getting-ready robe is the bridal, birthday and Sunday-reset pin all in one. | P6: BANK E23
A7: C006 | B7: Puffy / fluffy pink slippers and slides | C7: beauty-selfcare | D7: The Pink Bedtime Routine / Cozy Pink Home list | E7: Keyword page 'puffy slides' shows card with 5.7K sold at $17.28 (was $24.34, -29%) | F7: TikTok Shop | G7: https://shop.tiktok.com/us/k/puffy-slides | H7: 2026-09 (search snippet) | I7: seen in snippet | J7: TikTok Shop: Keyword page 'puffy slippers' shows card with 3.6K sold at $30.98 (flash sale) (https://shop.tiktok.com/us/k/puffy-slippers) | TikTok Shop: Keyword page 'pluffi slippers' shows card with 7.6K sold at $49.99 (branded, reference only) (https://shop.tiktok.com/us/k/pluffi-slippers) | K7: TikTok Shop $17.28 to $49.99 (snippet) | L7: unknown | M7: note: 'Pluffi' is a brand; sell generic puffy slides only, never as a dupe | N7: none | O7: Pillow-puffy pink slides are the shoe in every pink dorm and apartment flat lay. | P7: BANK E19
A8: C007 | B8: Silk / satin sleep mask (pink) | C8: beauty-selfcare | D8: The Pink Bedtime Routine / Travel Self-Care list | E8: Keyword page 'silk blindfold' shows card with 4.2K sold at $39.00 | F8: TikTok Shop | G8: https://shop.tiktok.com/us/k/silk-blindfold | H8: 2026-09 (search snippet) | I8: seen in snippet | K8: TikTok Shop up to $39 for mulberry silk (snippet); pink mulberry silk mask listing https://shop.tiktok.com/us/pdp/silk-sleep-mask-by-litbear-22-momme-mulberry-silk-eye-mask-for-comfort/1729436920505209656 | L8: unknown | M8: none (avoid 'Slip' brand references) | N8: note: touches face but is a textile accessory, not a cosmetic; no battery | O8: A pink silk mask with a bow is the cheapest 'luxury' item in the bedtime pin set. | P8: BANK E20
A9: C008 | B9: Hot pink desk / vanity organiser (multi-compartment) | C9: beauty-selfcare | D9: The Law School Desk Setup, All Pink / Pink Vanity Organisation list | E9: Keyword page 'hot pink desk organizer ideas' shows card with 7.7K sold at $10.99 (was $44.00, -75%) | F9: TikTok Shop | G9: https://shop.tiktok.com/us/k/hot-pink-desk-organizer-ideas | H9: 2026-09 (search snippet) | I9: seen in snippet | K9: TikTok Shop $10.99 (snippet) | L9: unknown | M9: none | N9: none | O9: Crosses over office and vanity: one hot-pink organiser that works on a desk or dresser gets saved to both boards. | P9: BANK E16
A10: C009 | B10: Glitter / pink makeup brush holder cup | C10: beauty-selfcare | D10: The Pink Vanity Organisation list | E10: Keyword page 'glitter makeup holder' shows card with 1.3K sold at $12.30 | F10: TikTok Shop | G10: https://shop.tiktok.com/us/k/glitter-makeup-holder | H10: 2026-09 (search snippet) | I10: seen in snippet | J10: TikTok Shop: Keyword page 'silicone makeup brush case' shows card with 170 sold at $5.45 (was $8.39, -35%) (https://shop.tiktok.com/us/k/silicone-makeup-brush-case) | K10: TikTok Shop $5.45 to $12.30 (snippet) | L10: AliExpress pearl acrylic brush holder with lid listed at US $11.50 https://www.aliexpress.com/item/M-makeup-brush-holder-pearls-organizer-acrylic-plastic-clear-cosmetic-brush-white-pink-pearls-storage-box/32954351202.html | M10: none | N10: none | O10: Pearl-filled or glitter brush cups are the detail shot in every pink vanity tour. | P10: BANK E14
A11: C010 | B11: Acrylic perfume / vanity display tray (2-tier or mirrored) | C11: beauty-selfcare | D11: The Pink Vanity Organisation / Perfume Shelf list | E11: Keyword page 'perfume vanity tray organizer' shows product cards with 25, 29, 55 and 1.5K sold | F11: TikTok Shop | G11: https://shop.tiktok.com/us/k/perfume-vanity-tray-organizer | H11: 2026-09 (search snippet) | I11: seen in snippet | J11: TikTok Shop: NiHome 2-Tier Acrylic Perfume Display Stand listing shows 173 sold (https://shop.tiktok.com/us/pdp/acrylic-perfume-display-stand-by-nihome-2-tier-organizer-for-vanity/1730302818778518451) | TikTok Shop: Keyword page 'perfume tray wooden' shows cards from 4 to 5,000 sold, one at 260 sold (https://shop.tiktok.com/us/k/perfume-tray-wooden) | TikTok Shop: Keyword page 'perfume tray' shows cards with 35, 195 and 461.7K sold (https://shop.tiktok.com/us/k/perfume-tray) | K11: unknown (prices not in snippet) | L11: unknown | M11: none | N11: none (tray only, no perfume) | O11: The perfume-tray shot is the most-saved vanity pin format; a pink or gold-trim tray sells the styling, not the scent. | P11: BANK E15
A12: C011 | B12: Heatless satin curling rod / headband set (pink) | C12: beauty-selfcare | D12: The Pink Bedtime Routine / Heatless Blowout list | E12: Keyword page 'home-bargains-heatless-curlers' shows card with 64 sold at $3.67 (was $19.99) | F12: TikTok Shop | G12: https://shop.tiktok.com/us/k/home-bargains-heatless-curlers | H12: 2026-09 (search snippet) | I12: seen in snippet | J12: TikTok Shop: Keyword page 'best heatless curle' shows card with 39 sold at $22.98 (https://shop.tiktok.com/us/k/best-heatless-curle) | TikTok Shop: Keyword page 'heatless curlers for short hair' shows card with 23 sold at $6.12 (https://shop.tiktok.com/us/k/heatless-curlers-for-short-hair) | Amazon Best Sellers: Amazon listing titled '2026 New Upgraded Eight Claw Design Satin Heatless Curling Rod' live (rank not in snippet) (https://www.amazon.com/clp/B0D4LWJT8P) | K12: TikTok Shop $3.67 to $22.98 (snippet); Kitsch branded set on TikTok Shop for reference https://shop.tiktok.com/us/pdp/kitsch-heatless-curling-rod-4pcs-jumbo-satin-hair-curlers-for-all-types/1729433840720515122 | L12: unknown (AliExpress prices not shown) | M12: note: avoid 'Kitsch' and 'BT21 x Kitsch' branded sets; generic satin rod only | N12: none | O12: Sold counts on TikTok are modest per SKU, but the pink 9-piece bundle (rod + bonnet + scrunchie + mask) is a ready-made 'heatless night routine' pin. | P12: BANK E22
A13: C012 | B13: Jewelry box / bracelet organiser (pink velvet or felt) | C13: beauty-selfcare | D13: The Pink Vanity Organisation / Gifting for Her list | E13: Keyword page 'jewellery boxes' shows card with 464 sold at -77% limited time deal | F13: TikTok Shop | G13: https://shop.tiktok.com/us/k/jewellery-boxes | H13: 2026-09 (search snippet) | I13: seen in snippet | K13: unknown (deal price not in snippet); pink felt bracelet box listing https://shop.tiktok.com/us/pdp/p6nk-jewelry-organizer-real-pink-felt-black-exterior/1732046163444142193 | L13: unknown | M13: none (skip 'Pandora' branded boxes seen at 79 sold) | N13: none | O13: A pink velvet jewelry box is the vanity pin that also gets saved as a gift idea. | P13: REJECT | Q13: Numeric signal exists but weaker than the 40 kept, or it duplicates a kept product in the same look.
A14: C013 | B14: Silicone makeup sponge holder (pink) | C14: beauty-selfcare | D14: The Pink Vanity Organisation list | E14: Keyword page 'makeup sponges holders' related listings show sold quantities ranging from 1 to 11.7K | F14: TikTok Shop | G14: https://shop.tiktok.com/us/k/makeup-sponges-holders | H14: 2026-09 (search snippet) | I14: unverified: 11.7K figure appeared in a related-search card; exact SKU not identified | K14: unknown; pink silicone holder listing https://shop.tiktok.com/us/pdp/silicone-makeup-sponge-holder-portable-durable-pink/1731600449249513992 | L14: unknown | M14: none | N14: none | O14: Tiny, cheap, pink, and solves the 'where do I dry my sponge' problem shown in every vanity tour. | P14: REJECT | Q14: Numeric signal exists but weaker than the 40 kept, or it duplicates a kept product in the same look.
A15: C014 | B15: Covered acrylic makeup organiser (dustproof lid) | C15: beauty-selfcare | D15: The Pink Vanity Organisation list | E15: Keyword page 'covered makeup organizer' shows card with 45 sold at $13.98 (was $28.99, -52%) | F15: TikTok Shop | G15: https://shop.tiktok.com/us/k/covered-makeup-organizer | H15: 2026-09 (search snippet) | I15: seen in snippet | K15: TikTok Shop $13.98 (snippet); Amazon Best Sellers Cosmetic Display Cases page https://www.amazon.com/Best-Sellers-Cosmetic-Display-Cases/zgbs/beauty/13861693011 (ranks not visible) | L15: AliExpress rotating pink acrylic organiser listed at US $179.98 (outlier, not a dropship price) https://www.aliexpress.com/item/Hot-Sale-Ailla-Pink-Acrylic-Makeup-Organizer-Rotating-Cosmetic-Tool-Cases-Jewelry-Storage-Holder/32802626744.html | M15: none | N15: none | O15: Clear-with-pink-lid organisers are the base layer of every pink vanity pin; weak sold signal so far, listed for completeness. | P15: BANK E18
A16: C015 | B16: Claw clip (pearl / rhinestone / jelly pink) | C16: beauty-selfcare | D16: The Girly Professional Hair Accessories list | E16: Keyword page 'claw clamps' shows card with 10 sold at $4.99 (limited time deal) | F16: TikTok Shop | G16: https://shop.tiktok.com/us/k/claw-clamps | H16: 2026-09 (search snippet) | I16: seen in snippet (weak) | J16: other: Who What Wear 2026: pearl and rhinestone claw clips and jelly claw clips called out as 2026 trend (no number) (https://www.whowhatwear.com/beauty/hair/hair-accessories-trends-2026) | K16: TikTok Shop $4.99 (snippet); jumbo fuchsia marble acetate clip listing https://shop.tiktok.com/us/pdp/hair-claw-by-ari-mae-jumbo-5-1-inch-fuchsia-marble-durable-acetate/1729403242832826423 | L16: unknown | M16: none | N16: none | O16: The office-to-gym pink claw clip is the low-cost add-on in every 'girly professional' desk pin. | P16: REJECT | Q16: Numeric signal exists but weaker than the 40 kept, or it duplicates a kept product in the same look.
A17: C016 | B17: Satin hair bow clip (oversized, pink) | C17: beauty-selfcare | D17: The Girly Professional Hair Accessories / Coquette Bow list | E17: Pinterest Predicts 2026 coverage: 'bows and ribbons remain en vogue', preppy headbands and 'wonky' clips named (no number in snippet) | F17: Pinterest Predicts | G17: https://beautymatter.com/articles/pinterest-predicts-2026 | H17: 2026 | I17: unverified: qualitative, no percentage seen | J17: other: Who What Wear summer 2026: 'oversized satin bow clips' named as trend, 2026 Golden Globes cited (no number) (https://www.whowhatwear.com/beauty/hair/hair-accessories-trends-summer-2026) | K17: unknown; Cider satin bow clip listing on TikTok Shop https://shop.tiktok.com/us/pdp/bow-satin-hair-clip-by-cider-available-in-3-colors-one-size/1729462576036286551 | L17: unknown | M17: none (generic bow) | N17: none | O17: The pink bow is the single most-pinned motif of the niche; no numeric sold count captured before search budget ran out. | P17: REJECT | Q17: Numeric signal exists but weaker than the 40 kept, or it duplicates a kept product in the same look.
A18: C017 | B18: Satin pillowcase (blush / hot pink, ruffle edge) | C18: beauty-selfcare | D18: The Pink Bedroom / Beauty Sleep list | E18: Hot pink satin pillowcase 2/4-pack and blush ruffle set listings live; sold counts not in snippet | F18: TikTok Shop | G18: https://shop.tiktok.com/us/pdp/hot-pink-satin-silk-pillowcases-cooling-envelope-closure/1729502446753716118 | H18: 2026-09 | I18: unverified: no sold count in snippet | K18: unknown | L18: unknown | M18: none | N18: none | O18: Blush ruffle satin pillowcases are the bed-styling pin that pairs with the bonnet and sleep mask. | P18: REJECT | Q18: No numeric signal found (listings exist, counts not visible in snippets).
A19: C018 | B19: Padded / preppy headband (pink, bow or pearl) | C19: beauty-selfcare | D19: The Girly Professional Hair Accessories list | E19: 2026 coverage names 'preppy headbands' as of-the-moment (no number) | F19: Pinterest Predicts | G19: https://beautymatter.com/articles/pinterest-predicts-2026 | H19: 2026 | I19: unverified: qualitative | K19: unknown; multiple pink padded headband listings on TikTok Shop e.g. https://shop.tiktok.com/us/pdp/preppy-pink-padded-headband-with-white-bows-sparkling-gems/1731919925721862765 | L19: unknown | M19: none | N19: none | O19: The pearl-trim pink padded headband is the 'law school' hair accessory. | P19: REJECT | Q19: No numeric signal found (listings exist, counts not visible in snippets).
A20: C019 | B20: Microfiber hair towel wrap (pink) | C20: beauty-selfcare | D20: The Everything Shower list | E20: NO SIGNAL | K20: unknown; TikTok Shop listings e.g. https://shop.tiktok.com/us/pdp/microfiber-hair-towel-wrap-by-formul-a-anti-frizz-super-absorbent-fast-drying/1731938102315487689 | L20: unknown | M20: none | N20: none | O20: Pink towel wrap plus spa headband is the post-shower pin. | P20: REJECT | Q20: No numeric signal found (listings exist, counts not visible in snippets).
A21: C020 | B21: Reusable satin-lined shower cap (pink) | C21: beauty-selfcare | D21: The Everything Shower list | E21: NO SIGNAL | K21: unknown; listing https://shop.tiktok.com/us/pdp/pink-shower-cap-reusable-high-quality-triple-layer-13-inch-diameter-perfect-for-long-hair-dreadlocks/1731429933936120751 | L21: unknown | M21: none (avoid Kitsch branded) | N21: none | O21: Bundles naturally with the bonnet and heatless rod set. | P21: REJECT | Q21: No numeric signal found (listings exist, counts not visible in snippets).
A22: C021 | B22: Satin scrunchie set (pink, oversized) | C22: beauty-selfcare | D22: The Girly Professional Hair Accessories list | E22: NO SIGNAL | K22: unknown; 60-pack listing https://shop.tiktok.com/us/pdp/satin-scrunchies-60-pack-by-silk-elegance-soft-hair-accessories-for-all/1729628567057961975 | L22: unknown | M22: none | N22: none | O22: Low-ticket add-on for the heatless / bonnet bundle. | P22: REJECT | Q22: No numeric signal found (listings exist, counts not visible in snippets).
A23: C022 | B23: Travel jewelry case (pink, small zip) | C23: beauty-selfcare | D23: The Pink Weekend Trip / Bridesmaid Gifting list | E23: NO SIGNAL | K23: unknown; 8-pc bridesmaid pink set listing https://shop.tiktok.com/us/pdp/acrylic-jewelry-box-by-unbranded-clear-organizer-with-15-zipper-bags/1730743806890972120 | L23: unknown | M23: none | N23: none | O23: Fits the travel flat lay with the vanity bag. | P23: REJECT | Q23: No numeric signal found (listings exist, counts not visible in snippets).
A24: C023 | B24: Hanging toiletry bag (pink) | C24: beauty-selfcare | D24: The Pink Weekend Trip list | E24: Keyword page 'western makeup bags pink' shows card with 10 sold at $32.43 (was $60.05, -46%) | F24: TikTok Shop | G24: https://shop.tiktok.com/us/k/western-makeup-bags-pink | H24: 2026-09 (search snippet) | I24: seen in snippet (weak) | K24: TikTok Shop $32.43 (snippet) | L24: unknown | M24: none | N24: none | O24: Secondary to the vanity bag; weak signal. | P24: REJECT | Q24: No numeric signal found (listings exist, counts not visible in snippets).
A25: C024 | B25: Bath caddy tray | C25: beauty-selfcare | D25: The Pink Everything Shower / Bath list | E25: Keyword page 'hygiene caddy' shows card with 1 sold at $8.16 | F25: TikTok Shop | G25: https://shop.tiktok.com/us/k/hygiene-caddy | H25: 2026-09 (search snippet) | I25: seen in snippet (negligible) | K25: unknown | L25: unknown | M25: none | N25: none | O25: Bath-tray pin format is strong but no sales number captured. | P25: REJECT | Q25: No numeric signal found (listings exist, counts not visible in snippets).
A26: C025 | B26: Nail care kit without glue (files, buffers, cuticle tools, pink case) | C26: beauty-selfcare | D26: The Pink Vanity / At-Home Manicure list | E26: NO SIGNAL | K26: unknown | L26: unknown | M26: none (avoid branded gel kits with UV lamps: battery/electronics) | N26: none if tools only | O26: Fits the manicure-Sunday pin; no numbers found before budget ran out. | P26: REJECT | Q26: No numeric signal found (listings exist, counts not visible in snippets).
A27: C026 | B27: Pink calming donut / raised dog bed | C27: dog | D27: Pink Home, Dorm and Car Finds - the pink dog corner | E27: Amazon search 'pink raised dog bed': top results show up to 5K+ bought in past month | F27: Amazon Best Sellers | G27: https://www.amazon.com/pink-raised-dog-bed/s?k=pink+raised+dog+bed | H27: 2026-09-27 | I27: seen in snippet (search-tool summary of Amazon results page; exact ASIN not shown) | J27: Amazon Best Sellers: Amazon search 'pink calming dog bed': popular options show 2K+ bought in past month (https://www.amazon.com/pink-calming-dog-bed/s?k=pink+calming+dog+bed) | Amazon Best Sellers: Amazon search 'pink puppy bed': some products 3K+ bought in past month (https://www.amazon.com/pink-puppy-bed/s?k=pink+puppy+bed) | Amazon Best Sellers: 'Non-Slip Bottom Egg-Crate Memory Foam Big Dog Couch Bed, Dusty Pink, 44 inch' 500+ bought in past month (https://www.amazon.com/dusty-pink-dog-bed/s?k=dusty+pink+dog+bed) | K27: unknown (Amazon price not shown in snippets) | L27: unknown | M27: none | N27: none | O27: A blush dog bed that matches the pink sofa is the flat-lay hero of every 'pink dog mom home' board. | P27: REJECT | Q27: Bulky or heavy: inbound shipping pushes the price out of the Pink Finds band.
A28: C027 | B28: Blush pink packing cubes set (6 to 8 pc) | C28: gifting | D28: Pink travel set / girls-trip packing list | E28: Amazon search 'pink packing cubes': products show from 50+ up to 4K+ bought in past month | F28: Amazon Best Sellers | G28: https://www.amazon.com/pink-packing-cubes/s?k=pink+packing+cubes | H28: 2026-09-27 | I28: seen in snippet (search-tool summary of Amazon results page; which listing carries 4K+ not shown) | J28: other: risingtrends/Glimpse jewelry-trends roundup: travel accessories saw an overall 16% sales increase in the first two months of 2026 (https://www.risingtrends.co/trends/jewelry-trends-2026) | K28: unknown; reference listing BAGAIL 8-set Blush Pink https://www.amazon.com/BAGAIL-Packing-Lightweight-Organizers-Toiletry/dp/B08S38PLQG (price not in snippet) | L28: unknown | M28: none (avoid BAGAIL/BEIS branding) | N28: none | O28: Colour-coordinated pink cubes inside an open suitcase is a classic 'pack with me' pin. | P28: BANK Q13
A29: C028 | B29: Pink velvet jewelry box with lock | C29: gifting | D29: Pink vanity / gifts for her under $40 | E29: Amazon search 'pink jewelry box': 100+ bought in past month; 'pink jewelry gift box': 200+ bought in past month; 'pink jewelry organizer': 50+ bought in past month | F29: Amazon Best Sellers | G29: https://www.amazon.com/pink-jewelry-box/s?k=pink+jewelry+box | H29: 2026-09-27 | I29: seen in snippet (search-tool summary of Amazon results pages) | J29: Amazon Best Sellers: QBestry pink velvet jewelry box with lock (B09SFQ2VGR) 50+ bought in past month (https://www.amazon.com/Organizer-QBestry-Necklace-Bracelets-Earrings/dp/B09SFQ2VGR) | TikTok Shop: TikTok Shop 'hot-pink-jewelry-box' page: items priced $9.99 to $89.99, several showing Sold status with 'thousands of units sold' (https://www.tiktok.com/shop/product/hot-pink-jewelry-box) | K29: $9.99 to $89.99 on TikTok Shop hot-pink jewelry box page (search summary) | L29: unknown | M29: none | N29: none | O29: A blush velvet box open on a marble vanity is the definitive 'gift for her' pin. | P29: BANK Q12
A30: C029 | B30: Pink travel jewelry case (small zip organizer) | C30: gifting | D30: Pink travel set / carry-on essentials | E30: Travel-jewelry products 'soared' in first two months of 2026; travel accessories +16% sales overall | F30: other | G30: https://www.risingtrends.co/trends/jewelry-trends-2026 | H30: 2026 (Jan-Feb) | I30: unverified: figure appeared in search summary; exact page not confirmed | J30: TikTok Shop: Travel jewelry organizer and 'travel jewelry boxes bulk' keyword pages exist on TikTok Shop US (no sold count captured) (https://www.tiktok.com/shop/product/jewelry-travel-organizer) | K30: unknown | L30: unknown | M30: none (avoid BAGSMART branding) | N30: none | O30: Fits the pink packing-cube flat lay; bundles naturally with luggage tag and passport cover. | P30: REJECT | Q30: Numeric signal exists but weaker than the 40 kept, or it duplicates a kept product in the same look.
A31: C030 | B31: Pink paper heart garland (6 ft) | C31: seasonal-valentines | D31: Pink Valentine's mantel / Galentine's table | E31: Etsy listing 'Red & Pink Heart Garland, 6ft strand' (anyoccasionbanners) has 622 favorites | F31: Etsy | G31: https://www.etsy.com/listing/118450280/red-pink-heart-garland-valentines-day | H31: 2026-09-27 | I31: seen in snippet | J31: Etsy: Etsy listing 'Cupid and Heart Garland' (same shop) 125 favorites (https://www.etsy.com/listing/260078255/cupid-and-heart-garland-valentines-day) | Pinterest Trends: Pinterest data: 'Valentine's decor' searches doubled (Forbes, Valentine's 2026 coverage) (https://www.forbes.com/sites/katehardcastle/2026/02/13/valentines-2026-how-galentines-and-friendship-spending-are-expanding-the-business-of-love/) | K31: unknown (Etsy price not in snippet) | L31: unknown | M31: none | N31: none | O31: Cheapest way to make a mantel or desk read 'pink Valentine's' in one pin. | P31: REJECT | Q31: Numeric signal exists but weaker than the 40 kept, or it duplicates a kept product in the same look.
A32: C031 | B32: Galentine's party kit (pink plates, napkins, banner, straws) | C32: seasonal-valentines | D32: Galentine's brunch table, all pink | E32: Pinterest data indicates a 50% rise in 'Galentine's aesthetic' searches | F32: Pinterest Trends | G32: https://www.forbes.com/sites/katehardcastle/2026/02/13/valentines-2026-how-galentines-and-friendship-spending-are-expanding-the-business-of-love/ | H32: 2026-02-13 | I32: seen in snippet | J32: other: 'Galentine's Day alone has surpassed 8.6 million searches, rising by 207%' (https://nationaltoday.com/us/ca/los-angeles/news/2026/02/13/galentines-and-friendship-spending-expand-the-modern-relationship-economy/) | other: Pinterest board '740 Best Galentine's Day Party Ideas in 2026' (prettycollected) holds 740 pins (https://www.pinterest.com/prettycollected/galentines-day-party-ideas/) | K32: unknown | L32: unknown | M32: none (keep text generic, no brand fonts) | N32: none | O32: Galentine's is the fastest-growing February occasion and it is pink by default. | P32: REJECT | Q32: Numeric signal exists but weaker than the 40 kept, or it duplicates a kept product in the same look.
A33: C032 | B33: Pink heart-shaped decor: heart pillow and heart-shaped tray | C33: seasonal-valentines | D33: Pink Valentine's living room / coffee table | E33: 'Valentine's decor' searches doubled on Pinterest (Forbes, Feb 2026) | F33: Pinterest Trends | G33: https://www.forbes.com/sites/katehardcastle/2026/02/13/valentines-2026-how-galentines-and-friendship-spending-are-expanding-the-business-of-love/ | H33: 2026-02-13 | I33: seen in snippet (category-level only; no product-level count found) | K33: unknown | L33: unknown | M33: none | N33: none | O33: Heart pillow on a cream sofa is the lowest-effort Valentine's room refresh. | P33: REJECT | Q33: Numeric signal exists but weaker than the 40 kept, or it duplicates a kept product in the same look.
A34: C033 | B34: Pink bow party decor kit (bow garland, bow cake topper, bow napkins) | C34: gifting | D34: Pink bow party / bow-themed gifts | E34: Pinterest board 'Pink Bow Grad Party ideas in 2026' holds 200 pins; Pinterest has dedicated 'Pink Bow Party' and 'Bow Party Decor' ideas hubs | F34: other | G34: https://www.pinterest.com/ideas/pink-bow-party/955183510608/ | H34: 2026 | I34: seen in snippet (board pin count, weak; no Pinterest Trends percentage captured) | J34: Pinterest Trends: 'Galentine's aesthetic' +50% (bow-themed Galentine's party pins sit inside this trend) (https://www.forbes.com/sites/katehardcastle/2026/02/13/valentines-2026-how-galentines-and-friendship-spending-are-expanding-the-business-of-love/) | K34: unknown | L34: unknown | M34: none (generic bows only) | N34: none | O34: Bows are the signature motif of the pink-girly aesthetic; a bow garland photographs well on any table. | P34: BANK Q07
A35: C034 | B35: Pink ruffle dog bandana with matching bow | C35: dog | D35: Girly dog accessories / dog mom gift list | E35: Etsy listing 'Girly Pink Striped Ruffle Bandana' carries the Bestseller badge ('high sales volume over the past 6 months'); priced EUR 27.41, EUR 31.06 with matching bow | F35: Etsy | G35: https://www.etsy.com/listing/1817731525/custom-embroidered-dog-bandana-girly-dog | H35: 2026-09-27 | I35: seen in snippet (badge, no exact sales count) | J35: Etsy: Etsy 'pink dog bow' market page: 1,000+ unique items listed, prices under GBP 20 to over GBP 100 (https://www.etsy.com/uk/market/pink_dog_bow) | K35: EUR 27.41 bandana / EUR 31.06 with bow (Etsy listing 1817731525) | L35: unknown | M35: none | N35: none | O35: Matching pink bow on the dog is the 'dog mom' pin; low cost, high save rate. | P35: REJECT | Q35: Numeric signal exists but weaker than the 40 kept, or it duplicates a kept product in the same look.
A36: C035 | B36: Pink bow-stem champagne flutes, set of 4 | C36: seasonal-nye | D36: Pink NYE bar cart / Galentine's toast | E36: TikTok Shop champagne-flute keyword page shows per-listing counts of 7, 3, 8 and 56 sold, prices $31.95 to $105.99 | F36: TikTok Shop | G36: https://shop.tiktok.com/us/k/swarovski-champagne-flutes | H36: 2026-09-27 | I36: seen in snippet (keyword page is branded 'swarovski'; counts are for adjacent listings, not the pink bow set) | J36: other: eBay listing 'Pink Bow Gem Champagne Flutes, TikTok Viral Set of 4' describes the set as TikTok-viral limited edition (https://www.ebay.com/itm/276803467251) | K36: unknown for the pink bow set; flutes on TikTok Shop page listed $31.95 to $105.99 | L36: unknown | M36: none (do not source Swarovski-branded items) | N36: none | O36: Bow-stem flutes with pink bubbly is the NYE-to-Valentine's crossover pin. | P36: BANK Q15
A37: C036 | B37: Pink plastic champagne flutes 5.5 oz, non-skid base (party pack) | C37: seasonal-nye | D37: Pink NYE party table | E37: NO SIGNAL | K37: unknown (Amazon listing seen via Movers & Shakers Home & Kitchen search, no rank or count in snippet) | L37: unknown | M37: none | N37: none | O37: Disposable-but-pretty flutes for a pink NYE table. | P37: REJECT | Q37: No numeric signal found (listings exist, counts not visible in snippets).
A38: C037 | B38: Pink bow dog harness, collar and leash set | C38: dog | D38: Girly dog accessories | E38: NO SIGNAL | K38: unknown; Amazon references Didog bow harness set B0C3RVZVND and pink bow-tie harness set B0C48YPPD9 (no counts in snippets) | L38: unknown | M38: none | N38: none | O38: The matching pink harness set is the most-saved dog mom accessory; needs a sales count. | P38: REJECT | Q38: No numeric signal found (listings exist, counts not visible in snippets).
A39: C038 | B39: Pink poop bag holder (velvet / strawberry / PU leather) | C39: dog | D39: Girly dog walk kit | E39: NO SIGNAL | K39: unknown; Amazon listings B0FPFRCT9R (strawberry pink), B0DRW54512 (pink), ARING PET velvet pink store page, no counts in snippets | L39: unknown | M39: none | N39: none | O39: Small pink add-on that completes the leash flat lay. | P39: REJECT | Q39: No numeric signal found (listings exist, counts not visible in snippets).
A40: C039 | B40: Pink pet carrier bag / bubble-window backpack | C40: dog | D40: Pink travel set with the dog | E40: NO SIGNAL | K40: unknown | L40: unknown | M40: none | N40: none | O40: Pink carrier plus pink luggage is the girls-trip-with-dog pin. | P40: REJECT | Q40: No numeric signal found (listings exist, counts not visible in snippets).
...

Sheet Suppliers
A1: Product ID | B1: Product | C1: Rank | D1: Supplier | E1: Supplier listing URL | F1: Product cost ($) | G1: Ship to GA 31808 ($) | H1: Ship to CA 90210 ($) | I1: Days to GA (min-max) | J1: Days to CA (min-max) | K1: Max quoted days | L1: Warehouse country | M1: MOQ | N1: Packaging | O1: Return policy | P1: Photos usable? | Q1: Verified? | R1: Notes
A2: Q01 | B2: Fluffy pink bunny ears headband | C2: winner | D2: CJ Dropshipping (US warehouse filter) | E2: https://cjdropshipping.com/search/plush+bunny+ears+headband+pink.html | F2: 7.7 | G2: 4.5 | H2: 4.5 | I2: 4 to 9 days (1 to 3 processing + 3 to 6 transit, cjdropshipping.com via snippet) | J2: 4 to 9 days (1 to 3 processing + 3 to 6 transit, cjdropshipping.com via snippet) | K2: 9 | L2: US (NJ or CA) | M2: 1 | N2: unbranded mailer (confirm) | O2: CJ: refund or resend for damaged, wrong or lost items; change-of-mind returns at buyer cost. Confirm on cjdropshipping.com (return policy page). | P2: listing photos usable for the product page after checking the supplier licence; pins use our generated images | Q2: estimate: cost = 40% of the US retail seen (Zendrop guide ratio $8 to $12 product on $25 retail); confirm on cjdropshipping.com | R2: Search 'plush bunny ears headband pink' with the US Warehouse filter on. Shipping: under 8 oz, estimate $4.50 (Zendrop $4 to $6 band). Colour of the 4.8K-sold variant not confirmed pink.
A3: Q01 | B3: Fluffy pink bunny ears headband | C3: backup | D3: Zendrop (Ships From: US filter) | E3: https://app.zendrop.com/ (search 'plush bunny ears headband pink', Ships From: US) | F3: 8.47 | G3: 4.5 | H3: 4.5 | I3: 3 to 11 days (1 to 3 business days processing + 2 to 8 days, support.zendrop.com via snippet) | J3: 3 to 11 days (1 to 3 business days processing + 2 to 8 days, support.zendrop.com via snippet) | K3: 11 | L3: US | M3: 1 | N3: unbranded mailer (confirm) | O3: Zendrop: refund or replacement for damaged or lost orders; change-of-mind returns not covered. Confirm on support.zendrop.com. | P3: listing photos usable for the product page after checking the supplier licence; pins use our generated images | Q3: estimate; confirm on app.zendrop.com | R3: Needs a paid Zendrop plan ($29/month for 1 to 20 linked products). Cost estimate = CJ estimate + 10%. Search 'plush bunny ears headband pink'.
A4: Q01 | B4: Fluffy pink bunny ears headband | C4: last-resort | D4: AliExpress Choice (non-US, last resort) | E4: https://www.aliexpress.us/w/wholesale-plush-bunny-ears-headband-pink.html | F4: 4.62 | G4: 0 | H4: 0 | I4: 7 to 15 days quoted on most Choice listings; exceeds the 10-day rule | J4: 7 to 15 days quoted on most Choice listings; exceeds the 10-day rule | K4: 15 | L4: China | M4: 1 | N4: unbranded mailer (confirm) | O4: AliExpress Choice: free returns within 15 days on Choice items per AliExpress; the store still owes the customer a US return route. Confirm on aliexpress.com. | P4: listing photos usable for the product page after checking the supplier licence; pins use our generated images | Q4: estimate; confirm on aliexpress.com | R4: EXCLUDED for Q4 (15+ day quote). Evergreen only if the US options fail AND margin is 10 points better. Duties apply since de minimis ended 29 Aug 2025.
A5: Q02 | B5: Pink velvet pumpkins, set of 12 | C5: winner | D5: CJ Dropshipping (US warehouse filter) | E5: https://cjdropshipping.com/search/velvet+pumpkin+set+pink+foam.html | F5: 8 | G5: 5.5 | H5: 5.5 | I5: 4 to 9 days (1 to 3 processing + 3 to 6 transit, cjdropshipping.com via snippet) | J5: 4 to 9 days (1 to 3 processing + 3 to 6 transit, cjdropshipping.com via snippet) | K5: 9 | L5: US (NJ or CA) | M5: 1 | N5: unbranded mailer (confirm) | O5: CJ: refund or resend for damaged, wrong or lost items; change-of-mind returns at buyer cost. Confirm on cjdropshipping.com (return policy page). | P5: listing photos usable for the product page after checking the supplier licence; pins use our generated images | Q5: estimate: cost = 40% of the US retail seen (Zendrop guide ratio $8 to $12 product on $25 retail); confirm on cjdropshipping.com | R5: Search 'velvet pumpkin set pink foam' with the US Warehouse filter on. Shipping: 8 oz to 1 lb, estimate $5.50 (CJ 'about $5' example).
A6: Q02 | B6: Pink velvet pumpkins, set of 12 | C6: backup | D6: Zendrop (Ships From: US filter) | E6: https://app.zendrop.com/ (search 'velvet pumpkin set pink foam', Ships From: US) | F6: 8.8 | G6: 5.5 | H6: 5.5 | I6: 3 to 11 days (1 to 3 business days processing + 2 to 8 days, support.zendrop.com via snippet) | J6: 3 to 11 days (1 to 3 business days processing + 2 to 8 days, support.zendrop.com via snippet) | K6: 11 | L6: US | M6: 1 | N6: unbranded mailer (confirm) | O6: Zendrop: refund or replacement for damaged or lost orders; change-of-mind returns not covered. Confirm on support.zendrop.com. | P6: listing photos usable for the product page after checking the supplier licence; pins use our generated images | Q6: estimate; confirm on app.zendrop.com | R6: Needs a paid Zendrop plan ($29/month for 1 to 20 linked products). Cost estimate = CJ estimate + 10%. Search 'velvet pumpkin set pink foam'.
A7: Q02 | B7: Pink velvet pumpkins, set of 12 | C7: last-resort | D7: AliExpress Choice (non-US, last resort) | E7: https://www.aliexpress.com/item/3256804340218119.html | F7: 4.8 | G7: 0 | H7: 0 | I7: 7 to 15 days quoted on most Choice listings; exceeds the 10-day rule | J7: 7 to 15 days quoted on most Choice listings; exceeds the 10-day rule | K7: 15 | L7: China | M7: 1 | N7: unbranded mailer (confirm) | O7: AliExpress Choice: free returns within 15 days on Choice items per AliExpress; the store still owes the customer a US return route. Confirm on aliexpress.com. | P7: listing photos usable for the product page after checking the supplier licence; pins use our generated images | Q7: estimate; confirm on aliexpress.com | R7: EXCLUDED for Q4 (15+ day quote). Evergreen only if the US options fail AND margin is 10 points better. Duties apply since de minimis ended 29 Aug 2025.
A8: Q03 | B8: Pink faux fur throw blanket, 50 by 60 | C8: winner | D8: CJ Dropshipping (US warehouse filter) | E8: https://cjdropshipping.com/search/faux+fur+throw+blanket+pink+50x60.html | F8: 12 | G8: 8.15 | H8: 8.15 | I8: 4 to 9 days (1 to 3 processing + 3 to 6 transit, cjdropshipping.com via snippet) | J8: 4 to 9 days (1 to 3 processing + 3 to 6 transit, cjdropshipping.com via snippet) | K8: 9 | L8: US (NJ or CA) | M8: 1 | N8: unbranded mailer (confirm) | O8: CJ: refund or resend for damaged, wrong or lost items; change-of-mind returns at buyer cost. Confirm on cjdropshipping.com (return policy page). | P8: listing photos usable for the product page after checking the supplier licence; pins use our generated images | Q8: estimate: cost = 40% of the US retail seen (Zendrop guide ratio $8 to $12 product on $25 retail); confirm on cjdropshipping.com | R8: Search 'faux fur throw blanket pink 50x60' with the US Warehouse filter on. Shipping: 1 to 2 lb, USPS Ground Advantage commercial 1 lb zone 4 $8.15 seen.
A9: Q03 | B9: Pink faux fur throw blanket, 50 by 60 | C9: backup | D9: Zendrop (Ships From: US filter) | E9: https://app.zendrop.com/ (search 'faux fur throw blanket pink 50x60', Ships From: US) | F9: 13.2 | G9: 8.15 | H9: 8.15 | I9: 3 to 11 days (1 to 3 business days processing + 2 to 8 days, support.zendrop.com via snippet) | J9: 3 to 11 days (1 to 3 business days processing + 2 to 8 days, support.zendrop.com via snippet) | K9: 11 | L9: US | M9: 1 | N9: unbranded mailer (confirm) | O9: Zendrop: refund or replacement for damaged or lost orders; change-of-mind returns not covered. Confirm on support.zendrop.com. | P9: listing photos usable for the product page after checking the supplier licence; pins use our generated images | Q9: estimate; confirm on app.zendrop.com | R9: Needs a paid Zendrop plan ($29/month for 1 to 20 linked products). Cost estimate = CJ estimate + 10%. Search 'faux fur throw blanket pink 50x60'.
A10: Q03 | B10: Pink faux fur throw blanket, 50 by 60 | C10: last-resort | D10: AliExpress Choice (non-US, last resort) | E10: https://www.aliexpress.us/w/wholesale-faux-fur-throw-blanket-pink-50x60.html | F10: 7.2 | G10: 0 | H10: 0 | I10: 7 to 15 days quoted on most Choice listings; exceeds the 10-day rule | J10: 7 to 15 days quoted on most Choice listings; exceeds the 10-day rule | K10: 15 | L10: China | M10: 1 | N10: unbranded mailer (confirm) | O10: AliExpress Choice: free returns within 15 days on Choice items per AliExpress; the store still owes the customer a US return route. Confirm on aliexpress.com. | P10: listing photos usable for the product page after checking the supplier licence; pins use our generated images | Q10: estimate; confirm on aliexpress.com | R10: EXCLUDED for Q4 (15+ day quote). Evergreen only if the US options fail AND margin is 10 points better. Duties apply since de minimis ended 29 Aug 2025.
A11: Q04 | B11: Pink velvet throw pillow covers, pair | C11: winner | D11: CJ Dropshipping (US warehouse filter) | E11: https://cjdropshipping.com/search/velvet+pillow+cover+pink+18x18.html | F11: 6 | G11: 4.5 | H11: 4.5 | I11: 4 to 9 days (1 to 3 processing + 3 to 6 transit, cjdropshipping.com via snippet) | J11: 4 to 9 days (1 to 3 processing + 3 to 6 transit, cjdropshipping.com via snippet) | K11: 9 | L11: US (NJ or CA) | M11: 1 | N11: unbranded mailer (confirm) | O11: CJ: refund or resend for damaged, wrong or lost items; change-of-mind returns at buyer cost. Confirm on cjdropshipping.com (return policy page). | P11: listing photos usable for the product page after checking the supplier licence; pins use our generated images | Q11: estimate: cost = 40% of the US retail seen (Zendrop guide ratio $8 to $12 product on $25 retail); confirm on cjdropshipping.com | R11: Search 'velvet pillow cover pink 18x18' with the US Warehouse filter on. Shipping: under 8 oz, estimate $4.50 (Zendrop $4 to $6 band).
A12: Q04 | B12: Pink velvet throw pillow covers, pair | C12: backup | D12: Zendrop (Ships From: US filter) | E12: https://app.zendrop.com/ (search 'velvet pillow cover pink 18x18', Ships From: US) | F12: 6.6 | G12: 4.5 | H12: 4.5 | I12: 3 to 11 days (1 to 3 business days processing + 2 to 8 days, support.zendrop.com via snippet) | J12: 3 to 11 days (1 to 3 business days processing + 2 to 8 days, support.zendrop.com via snippet) | K12: 11 | L12: US | M12: 1 | N12: unbranded mailer (confirm) | O12: Zendrop: refund or replacement for damaged or lost orders; change-of-mind returns not covered. Confirm on support.zendrop.com. | P12: listing photos usable for the product page after checking the supplier licence; pins use our generated images | Q12: estimate; confirm on app.zendrop.com | R12: Needs a paid Zendrop plan ($29/month for 1 to 20 linked products). Cost estimate = CJ estimate + 10%. Search 'velvet pillow cover pink 18x18'.
A13: Q04 | B13: Pink velvet throw pillow covers, pair | C13: last-resort | D13: AliExpress Choice (non-US, last resort) | E13: https://www.aliexpress.us/w/wholesale-velvet-pillow-cover-pink-18x18.html | F13: 3.6 | G13: 0 | H13: 0 | I13: 7 to 15 days quoted on most Choice listings; exceeds the 10-day rule | J13: 7 to 15 days quoted on most Choice listings; exceeds the 10-day rule | K13: 15 | L13: China | M13: 1 | N13: unbranded mailer (confirm) | O13: AliExpress Choice: free returns within 15 days on Choice items per AliExpress; the store still owes the customer a US return route. Confirm on aliexpress.com. | P13: listing photos usable for the product page after checking the supplier licence; pins use our generated images | Q13: estimate; confirm on aliexpress.com | R13: EXCLUDED for Q4 (15+ day quote). Evergreen only if the US options fail AND margin is 10 points better. Duties apply since de minimis ended 29 Aug 2025.
... A121: E24 | B121: Cream hooded wearable blanket | C121: last-resort | D121: AliExpress Choice (non-US, last resort) | E121: https://www.aliexpress.us/w/wholesale-hooded-wearable-blanket-fleece-cream.html | F121: 5.4 | G121: 0 | H121: 0 | I121: 7 to 15 days quoted on most Choice listings; exceeds the 10-day rule | J121: 7 to 15 days quoted on most Choice listings; exceeds the 10-day rule | K121: 15 | L121: China | M121: 1 | N121: unbranded mailer (confirm) | O121: AliExpress Choice: free returns within 15 days on Choice items per AliExpress; the store still owes the customer a US return route. Confirm on aliexpress.com. | P121: listing photos usable for the product page after checking the supplier licence; pins use our generated images | Q121: estimate; confirm on aliexpress.com | R121: EXCLUDED for Q4 (15+ day quote). Evergreen only if the US options fail AND margin is 10 points better. Duties apply since de minimis ended 29 Aug 2025.

Sheet Margins
A1: ASSUMPTIONS (blue cells are inputs; change them and every row recalculates)
A2: Orders per month (amortisation base) | B2: 30 | C2: Job D1 brief assumes 30 orders/month
A3: Platform monthly fee ($) | B3: 39 | C3: Shopify Basic, monthly billing, $39/month (help.shopify.com Basic plan page via search snippet, 2026; $1/month for the first 3 months intro offer not modelled). Confirm on shopify.com/pricing.
A4: Fulfilment app monthly fee ($) | B4: 0 | C4: CJ Dropshipping Shopify app: no subscription fee (cjdropshipping.com blog and revenuegeeks, 2026, via snippet). If Zendrop is used instead, enter 29 (1 to 20 linked products) or 49 (21 to 100 products, usage-based billing per support.zendrop.com).
A5: Payment processing rate | B5: 0.029 | C5: 2.9% per the brief (Shopify Payments Basic online rate, confirm on shopify.com/pricing)
A6: Payment processing fixed ($) | B6: 0.3 | C6: $0.30 per the brief
A7: Return allowance (share of price) | B7: 0.08 | C7: 8% of sale price per the brief
A8: Packaging per order ($) | B8: 0.5 | C8: CJ US warehouse ships in its own unbranded mailer at no extra fee (revenuegeeks CJ pricing page via snippet); $0.50 covers an insert card or tissue. Confirm on cjdropshipping.com/service-fee.
A9: CAC scenario 2 ($ per order) | B9: 5 | C9: $5 CAC scenario per the brief; scenario 1 is $0 (Pinterest and email traffic)
A10: Margin floor at $0 CAC | B10: 0.45 | C10: 45% per the brief
A11: Margin floor at $5 CAC | B11: 0.25 | C11: 25% per the brief
A12: Price band: core ceiling ($) | B12: 50 | C12: Pink Finds price bands: the growth plan copy in the repo names no dollar bands, so the factory's price rule is used (section 3: mostly under $50, one splurge per look; window 5: 'under 25' gift guides). Flagged in REPORT.md.
A13: Price band: splurge ceiling ($) | B13: 79 | C13: one splurge allowed per look (factory section 3)
A15: Fixed monthly cost ($) = platform + app | B15: =B3+B4 -> 39
A16: Fee share per order ($) = fixed / orders | B16: =B15/B2 -> 1.3
A17: Sales tax: collected at checkout from the buyer and remitted; not a cost line. Nexus: Georgia on day one (see LEGAL_SETUP_CHECKLIST.md).
A19: ID | B19: Product | C19: Winner supplier | D19: Warehouse | E19: Product cost ($) | F19: Inbound shipping ($) | G19: Packaging ($) | H19: Sale price ($) | I19: Payment processing ($) | J19: App fee share ($) | K19: Return allowance ($) | L19: CAC scenario 1 ($) | M19: CAC scenario 2 ($) | N19: Total cost @ $0 CAC ($) | O19: Gross margin $ @ $0 CAC | P19: Gross margin % @ $0 CAC | Q19: Gross margin $ @ $5 CAC | R19: Gross margin % @ $5 CAC | S19: Break-even units/month | T19: Passes floors? | U19: Free shipping folded in? | V19: Price band | W19: Band OK? | X19: Verified?
A20: Q01 | B20: Fluffy pink bunny ears headband | C20: CJ Dropshipping (US warehouse filter) | D20: US (NJ or CA) | E20: 7.7 | F20: 4.5 | G20: =$B$8 -> 0.5 | H20: 32.99 | I20: =H20*$B$5+$B$6 -> 1.25671 | J20: =$B$16 -> 1.3 | K20: =H20*$B$7 -> 2.6392 | L20: 0 | M20: =$B$9 -> 5 | N20: =E20+F20+G20+I20+J20+K20+L20 -> 17.89591 | O20: =H20-N20 -> 15.09409 | P20: =IF(H20=0,0,O20/H20) -> 0.45753531 | Q20: =O20-M20 -> 10.09409 | R20: =IF(H20=0,0,Q20/H20) -> 0.30597423 | S20: =IF((H20-E20-F20-G20-I20-K20)<=0,"never",ROUNDUP($B$15/(H20-E20-F20-G20-I20-K20),0)) -> 3 | T20: =IF(AND(P20>=$B$10,R20>=$B$11),"PASS","KILL") -> PASS | U20: yes, folded into price | V20: core (under $50) | W20: =IF(H20<=$B$12,"core",IF(H20<=$B$13,"splurge","OUT OF BAND")) -> core | X20: estimate: cost = 40% of the US retail seen (Zendrop guide ratio $8 to $12 product on $25 retail); confirm on cjdropshipping.com
A21: Q02 | B21: Pink velvet pumpkins, set of 12 | C21: CJ Dropshipping (US warehouse filter) | D21: US (NJ or CA) | E21: 8 | F21: 5.5 | G21: =$B$8 -> 0.5 | H21: 35.99 | I21: =H21*$B$5+$B$6 -> 1.34371 | J21: =$B$16 -> 1.3 | K21: =H21*$B$7 -> 2.8792 | L21: 0 | M21: =$B$9 -> 5 | N21: =E21+F21+G21+I21+J21+K21+L21 -> 19.52291 | O21: =H21-N21 -> 16.46709 | P21: =IF(H21=0,0,O21/H21) -> 0.45754626 | Q21: =O21-M21 -> 11.46709 | R21: =IF(H21=0,0,Q21/H21) -> 0.31861878 | S21: =IF((H21-E21-F21-G21-I21-K21)<=0,"never",ROUNDUP($B$15/(H21-E21-F21-G21-I21-K21),0)) -> 3 | T21: =IF(AND(P21>=$B$10,R21>=$B$11),"PASS","KILL") -> PASS | U21: yes, folded into price | V21: core (under $50) | W21: =IF(H21<=$B$12,"core",IF(H21<=$B$13,"splurge","OUT OF BAND")) -> core | X21: estimate: cost = 40% of the US retail seen (Zendrop guide ratio $8 to $12 product on $25 retail); confirm on cjdropshipping.com
A22: Q03 | B22: Pink faux fur throw blanket, 50 by 60 | C22: CJ Dropshipping (US warehouse filter) | D22: US (NJ or CA) | E22: 12 | F22: 8.15 | G22: =$B$8 -> 0.5 | H22: 50.99 | I22: =H22*$B$5+$B$6 -> 1.77871 | J22: =$B$16 -> 1.3 | K22: =H22*$B$7 -> 4.0792 | L22: 0 | M22: =$B$9 -> 5 | N22: =E22+F22+G22+I22+J22+K22+L22 -> 27.80791 | O22: =H22-N22 -> 23.18209 | P22: =IF(H22=0,0,O22/H22) -> 0.45463993 | Q22: =O22-M22 -> 18.18209 | R22: =IF(H22=0,0,Q22/H22) -> 0.35658149 | S22: =IF((H22-E22-F22-G22-I22-K22)<=0,"never",ROUNDUP($B$15/(H22-E22-F22-G22-I22-K22),0)) -> 2 | T22: =IF(AND(P22>=$B$10,R22>=$B$11),"PASS","KILL") -> PASS | U22: yes, folded into price | V22: splurge (one per look) | W22: =IF(H22<=$B$12,"core",IF(H22<=$B$13,"splurge","OUT OF BAND")) -> splurge | X22: estimate: cost = 40% of the US retail seen (Zendrop guide ratio $8 to $12 product on $25 retail); confirm on cjdropshipping.com
A23: Q04 | B23: Pink velvet throw pillow covers, pair | C23: CJ Dropshipping (US warehouse filter) | D23: US (NJ or CA) | E23: 6 | F23: 4.5 | G23: =$B$8 -> 0.5 | H23: 28.99 | I23: =H23*$B$5+$B$6 -> 1.14071 | J23: =$B$16 -> 1.3 | K23: =H23*$B$7 -> 2.3192 | L23: 0 | M23: =$B$9 -> 5 | N23: =E23+F23+G23+I23+J23+K23+L23 -> 15.75991 | O23: =H23-N23 -> 13.23009 | P23: =IF(H23=0,0,O23/H23) -> 0.45636737 | Q23: =O23-M23 -> 8.23009 | R23: =IF(H23=0,0,Q23/H23) -> 0.2838941 | S23: =IF((H23-E23-F23-G23-I23-K23)<=0,"never",ROUNDUP($B$15/(H23-E23-F23-G23-I23-K23),0)) -> 3 | T23: =IF(AND(P23>=$B$10,R23>=$B$11),"PASS","KILL") -> PASS | U23: yes, folded into price | V23: core (under $50) | W23: =IF(H23<=$B$12,"core",IF(H23<=$B$13,"splurge","OUT OF BAND")) -> core | X23: estimate: cost = 40% of the US retail seen (Zendrop guide ratio $8 to $12 product on $25 retail); confirm on cjdropshipping.com
A24: Q05 | B24: Pink reusable party cups, 16 oz pack | C24: CJ Dropshipping (US warehouse filter) | D24: US (NJ or CA) | E24: 10.4 | F24: 5.5 | G24: =$B$8 -> 0.5 | H24: 40.99 | I24: =H24*$B$5+$B$6 -> 1.48871 | J24: =$B$16 -> 1.3 | K24: =H24*$B$7 -> 3.2792 | L24: 0 | M24: =$B$9 -> 5 | N24: =E24+F24+G24+I24+J24+K24+L24 -> 22.46791 | O24: =H24-N24 -> 18.52209 | P24: =IF(H24=0,0,O24/H24) -> 0.4518685 | Q24: =O24-M24 -> 13.52209 | R24: =IF(H24=0,0,Q24/H24) -> 0.32988753 | S24: =IF((H24-E24-F24-G24-I24-K24)<=0,"never",ROUNDUP($B$15/(H24-E24-F24-G24-I24-K24),0)) -> 2 | T24: =IF(AND(P24>=$B$10,R24>=$B$11),"PASS","KILL") -> PASS | U24: yes, folded into price | V24: core (under $50) | W24: =IF(H24<=$B$12,"core",IF(H24<=$B$13,"splurge","OUT OF BAND")) -> core | X24: estimate: cost = 40% of the US retail seen (Zendrop guide ratio $8 to $12 product on $25 retail); confirm on cjdropshipping.com
A25: Q06 | B25: Pink velvet Christmas tree bows, 24 pack | C25: CJ Dropshipping (US warehouse filter) | D25: US (NJ or CA) | E25: 7 | F25: 5.5 | G25: =$B$8 -> 0.5 | H25: 33.99 | I25: =H25*$B$5+$B$6 -> 1.28571 | J25: =$B$16 -> 1.3 | K25: =H25*$B$7 -> 2.7192 | L25: 0 | M25: =$B$9 -> 5 | N25: =E25+F25+G25+I25+J25+K25+L25 -> 18.30491 | O25: =H25-N25 -> 15.68509 | P25: =IF(H25=0,0,O25/H25) -> 0.4614619 | Q25: =O25-M25 -> 10.68509 | R25: =IF(H25=0,0,Q25/H25) -> 0.31435981 | S25: =IF((H25-E25-F25-G25-I25-K25)<=0,"never",ROUNDUP($B$15/(H25-E25-F25-G25-I25-K25),0)) -> 3 | T25: =IF(AND(P25>=$B$10,R25>=$B$11),"PASS","KILL") -> PASS | U25: yes, folded into price | V25: core (under $50) | W25: =IF(H25<=$B$12,"core",IF(H25<=$B$13,"splurge","OUT OF BAND")) -> core | X25: estimate: cost = 40% of the US retail seen (Zendrop guide ratio $8 to $12 product on $25 retail); confirm on cjdropshipping.com
A26: Q07 | B26: Pink velvet bow garland, 6 ft | C26: CJ Dropshipping (US warehouse filter) | D26: US (NJ or CA) | E26: 8 | F26: 5.5 | G26: =$B$8 -> 0.5 | H26: 35.99 | I26: =H26*$B$5+$B$6 -> 1.34371 | J26: =$B$16 -> 1.3 | K26: =H26*$B$7 -> 2.8792 | L26: 0 | M26: =$B$9 -> 5 | N26: =E26+F26+G26+I26+J26+K26+L26 -> 19.52291 | O26: =H26-N26 -> 16.46709 | P26: =IF(H26=0,0,O26/H26) -> 0.45754626 | Q26: =O26-M26 -> 11.46709 | R26: =IF(H26=0,0,Q26/H26) -> 0.31861878 | S26: =IF((H26-E26-F26-G26-I26-K26)<=0,"never",ROUNDUP($B$15/(H26-E26-F26-G26-I26-K26),0)) -> 3 | T26: =IF(AND(P26>=$B$10,R26>=$B$11),"PASS","KILL") -> PASS | U26: yes, folded into price | V26: core (under $50) | W26: =IF(H26<=$B$12,"core",IF(H26<=$B$13,"splurge","OUT OF BAND")) -> core | X26: estimate: cost = 40% of the US retail seen (Zendrop guide ratio $8 to $12 product on $25 retail); confirm on cjdropshipping.com
A27: Q08 | B27: Pink shatterproof ornament set, 45 pieces | C27: CJ Dropshipping (US warehouse filter) | D27: US (NJ or CA) | E27: 9 | F27: 8.15 | G27: =$B$8 -> 0.5 | H27: 43.99 | I27: =H27*$B$5+$B$6 -> 1.57571 | J27: =$B$16 -> 1.3 | K27: =H27*$B$7 -> 3.5192 | L27: 0 | M27: =$B$9 -> 5 | N27: =E27+F27+G27+I27+J27+K27+L27 -> 24.04491 | O27: =H27-N27 -> 19.94509 | P27: =IF(H27=0,0,O27/H27) -> 0.45340055 | Q27: =O27-M27 -> 14.94509 | R27: =IF(H27=0,0,Q27/H27) -> 0.33973835 | S27: =IF((H27-E27-F27-G27-I27-K27)<=0,"never",ROUNDUP($B$15/(H27-E27-F27-G27-I27-K27),0)) -> 2 | T27: =IF(AND(P27>=$B$10,R27>=$B$11),"PASS","KILL") -> PASS | U27: yes, folded into price | V27: core (under $50) | W27: =IF(H27<=$B$12,"core",IF(H27<=$B$13,"splurge","OUT OF BAND")) -> core | X27: estimate: cost = 40% of the US retail seen (Zendrop guide ratio $8 to $12 product on $25 retail); confirm on cjdropshipping.com
A28: Q09 | B28: Pink velvet Christmas stocking with bow | C28: CJ Dropshipping (US warehouse filter) | D28: US (NJ or CA) | E28: 5 | F28: 4.5 | G28: =$B$8 -> 0.5 | H28: 26.99 | I28: =H28*$B$5+$B$6 -> 1.08271 | J28: =$B$16 -> 1.3 | K28: =H28*$B$7 -> 2.1592 | L28: 0 | M28: =$B$9 -> 5 | N28: =E28+F28+G28+I28+J28+K28+L28 -> 14.54191 | O28: =H28-N28 -> 12.44809 | P28: =IF(H28=0,0,O28/H28) -> 0.46121119 | Q28: =O28-M28 -> 7.44809 | R28: =IF(H28=0,0,Q28/H28) -> 0.27595739 | S28: =IF((H28-E28-F28-G28-I28-K28)<=0,"never",ROUNDUP($B$15/(H28-E28-F28-G28-I28-K28),0)) -> 3 | T28: =IF(AND(P28>=$B$10,R28>=$B$11),"PASS","KILL") -> PASS | U28: yes, folded into price | V28: core (under $50) | W28: =IF(H28<=$B$12,"core",IF(H28<=$B$13,"splurge","OUT OF BAND")) -> core | X28: estimate: cost = 40% of the US retail seen (Zendrop guide ratio $8 to $12 product on $25 retail); confirm on cjdropshipping.com
A29: Q10 | B29: Pink flocked tabletop Christmas tree, 2 ft, unlit | C29: CJ Dropshipping (US warehouse filter) | D29: US (NJ or CA) | E29: 12 | F29: 8.15 | G29: =$B$8 -> 0.5 | H29: 50.99 | I29: =H29*$B$5+$B$6 -> 1.77871 | J29: =$B$16 -> 1.3 | K29: =H29*$B$7 -> 4.0792 | L29: 0 | M29: =$B$9 -> 5 | N29: =E29+F29+G29+I29+J29+K29+L29 -> 27.80791 | O29: =H29-N29 -> 23.18209 | P29: =IF(H29=0,0,O29/H29) -> 0.45463993 | Q29: =O29-M29 -> 18.18209 | R29: =IF(H29=0,0,Q29/H29) -> 0.35658149 | S29: =IF((H29-E29-F29-G29-I29-K29)<=0,"never",ROUNDUP($B$15/(H29-E29-F29-G29-I29-K29),0)) -> 2 | T29: =IF(AND(P29>=$B$10,R29>=$B$11),"PASS","KILL") -> PASS | U29: yes, folded into price | V29: splurge (one per look) | W29: =IF(H29<=$B$12,"core",IF(H29<=$B$13,"splurge","OUT OF BAND")) -> splurge | X29: estimate: cost = 40% of the US retail seen (Zendrop guide ratio $8 to $12 product on $25 retail); confirm on cjdropshipping.com
A30: Q11 | B30: Pink 40 oz insulated tumbler with handle and straw | C30: CJ Dropshipping (US warehouse filter) | D30: US (NJ or CA) | E30: 9 | F30: 8.15 | G30: =$B$8 -> 0.5 | H30: 43.99 | I30: =H30*$B$5+$B$6 -> 1.57571 | J30: =$B$16 -> 1.3 | K30: =H30*$B$7 -> 3.5192 | L30: 0 | M30: =$B$9 -> 5 | N30: =E30+F30+G30+I30+J30+K30+L30 -> 24.04491 | O30: =H30-N30 -> 19.94509 | P30: =IF(H30=0,0,O30/H30) -> 0.45340055 | Q30: =O30-M30 -> 14.94509 | R30: =IF(H30=0,0,Q30/H30) -> 0.33973835 | S30: =IF((H30-E30-F30-G30-I30-K30)<=0,"never",ROUNDUP($B$15/(H30-E30-F30-G30-I30-K30),0)) -> 2 | T30: =IF(AND(P30>=$B$10,R30>=$B$11),"PASS","KILL") -> PASS | U30: yes, folded into price | V30: core (under $50) | W30: =IF(H30<=$B$12,"core",IF(H30<=$B$13,"splurge","OUT OF BAND")) -> core | X30: listing found via search; price not visible in snippet, cost is an estimate; confirm on cjdropshipping.com
A31: Q12 | B31: Pink velvet jewelry box with lock | C31: CJ Dropshipping (US warehouse filter) | D31: US (NJ or CA) | E31: 10 | F31: 5.5 | G31: =$B$8 -> 0.5 | H31: 39.99 | I31: =H31*$B$5+$B$6 -> 1.45971 | J31: =$B$16 -> 1.3 | K31: =H31*$B$7 -> 3.1992 | L31: 0 | M31: =$B$9 -> 5 | N31: =E31+F31+G31+I31+J31+K31+L31 -> 21.95891 | O31: =H31-N31 -> 18.03109 | P31: =IF(H31=0,0,O31/H31) -> 0.45088997 | Q31: =O31-M31 -> 13.03109 | R31: =IF(H31=0,0,Q31/H31) -> 0.32585871 | S31: =IF((H31-E31-F31-G31-I31-K31)<=0,"never",ROUNDUP($B$15/(H31-E31-F31-G31-I31-K31),0)) -> 3 | T31: =IF(AND(P31>=$B$10,R31>=$B$11),"PASS","KILL") -> PASS | U31: yes, folded into price | V31: core (under $50) | W31: =IF(H31<=$B$12,"core",IF(H31<=$B$13,"splurge","OUT OF BAND")) -> core | X31: estimate: cost = 40% of the US retail seen (Zendrop guide ratio $8 to $12 product on $25 retail); confirm on cjdropshipping.com
... A59: E24 | B59: Cream hooded wearable blanket | C59: CJ Dropshipping (US warehouse filter) | D59: US (NJ or CA) | E59: 9 | F59: 8.15 | G59: =$B$8 -> 0.5 | H59: 43.99 | I59: =H59*$B$5+$B$6 -> 1.57571 | J59: =$B$16 -> 1.3 | K59: =H59*$B$7 -> 3.5192 | L59: 0 | M59: =$B$9 -> 5 | N59: =E59+F59+G59+I59+J59+K59+L59 -> 24.04491 | O59: =H59-N59 -> 19.94509 | P59: =IF(H59=0,0,O59/H59) -> 0.45340055 | Q59: =O59-M59 -> 14.94509 | R59: =IF(H59=0,0,Q59/H59) -> 0.33973835 | S59: =IF((H59-E59-F59-G59-I59-K59)<=0,"never",ROUNDUP($B$15/(H59-E59-F59-G59-I59-K59),0)) -> 2 | T59: =IF(AND(P59>=$B$10,R59>=$B$11),"PASS","KILL") -> PASS | U59: yes, folded into price | V59: core (under $50) | W59: =IF(H59<=$B$12,"core",IF(H59<=$B$13,"splurge","OUT OF BAND")) -> core | X59: estimate: cost = 40% of the US retail seen (Zendrop guide ratio $8 to $12 product on $25 retail); confirm on cjdropshipping.com
A61: Notes
